Workbook

Sheet all_6ppm
A1: time_1 | B1: 20_1 | C1: time_2 | D1: 37_1 | E1: time_3 | F1: 37_2 | G1: time_4 | H1: 42_1 | I1: time_5 | J1: 42_2 | K1: time_6 | L1: 48_1 | M1: time_7 | N1: 48_2
A2: ='20_1'!A64 -> 978 | B2: ='20_1'!M64 -> 0.92627837 | C2: ='37_1'!A40 -> 483 | D2: ='37_1'!M40 -> 0.96785221 | E2: ='37_2'!A76 -> 433 | F2: ='37_2'!M76 -> 0.99294787 | G2: ='42_1'!A28 -> 490 | H2: ='42_1'!M28 -> 0.97511309 | I2: ='42_2'!A26 -> 404 | J2: ='42_2'!M26 -> 0.98283065 | K2: 288 | L2: 0.97731083 | M2: ='48_2'!A24 -> 365 | N2: ='48_2'!M24 -> 0.98088243
A3: ='20_1'!A65 -> 1581 | B3: ='20_1'!M65 -> 0.93404895 | C3: ='37_1'!A41 -> 635 | D3: ='37_1'!M41 -> 0.95668219 | E3: ='37_2'!A77 -> 585 | F3: ='37_2'!M77 -> 0.97720247 | G3: ='42_1'!A29 -> 612 | H3: ='42_1'!M29 -> 0.96648517 | I3: ='42_2'!A27 -> 526 | J3: ='42_2'!M27 -> 0.9868019 | K3: 380 | L3: 0.97365721 | M3: ='48_2'!A25 -> 456 | N3: ='48_2'!M25 -> 0.97706905
A4: ='20_1'!A66 -> 2183 | B4: ='20_1'!M66 -> 0.94313685 | C4: ='37_1'!A42 -> 787 | D4: ='37_1'!M42 -> 0.95335947 | E4: ='37_2'!A78 -> 737 | F4: ='37_2'!M78 -> 0.97341623 | G4: ='42_1'!A30 -> 734 | H4: ='42_1'!M30 -> 0.96280303 | I4: ='42_2'!A28 -> 648 | J4: ='42_2'!M28 -> 0.96886905 | K4: 472 | L4: 0.97107693 | M4: ='48_2'!A26 -> 548 | N4: ='48_2'!M26 -> 0.96885987
A5: ='20_1'!A67 -> 2786 | B5: ='20_1'!M67 -> 0.99080119 | C5: ='37_1'!A43 -> 939 | D5: ='37_1'!M43 -> 0.94712662 | E5: ='37_2'!A79 -> 889 | F5: ='37_2'!M79 -> 0.96562862 | G5: ='42_1'!A31 -> 856 | H5: ='42_1'!M31 -> 0.96380006 | I5: ='42_2'!A29 -> 770 | J5: ='42_2'!M29 -> 0.96236358 | K5: 564 | L5: 0.96761648 | M5: ='48_2'!A27 -> 640 | N5: ='48_2'!M27 -> 0.96458885
A6: ='20_1'!A68 -> 3389 | B6: ='20_1'!M68 -> 0.98963107 | C6: ='37_1'!A44 -> 1090 | D6: ='37_1'!M44 -> 0.94769981 | E6: ='37_2'!A80 -> 1040 | F6: ='37_2'!M80 -> 0.9617043 | G6: ='42_1'!A32 -> 977 | H6: ='42_1'!M32 -> 0.95410835 | I6: ='42_2'!A30 -> 892 | J6: ='42_2'!M30 -> 0.96331107 | K6: 656 | L6: 0.96341322 | M6: ='48_2'!A28 -> 732 | N6: ='48_2'!M28 -> 0.96688114
A7: ='20_1'!A69 -> 3992 | B7: ='20_1'!M69 -> 0.98952461 | C7: ='37_1'!A45 -> 1242 | D7: ='37_1'!M45 -> 0.94233066 | E7: ='37_2'!A81 -> 1192 | F7: ='37_2'!M81 -> 0.95604653 | G7: ='42_1'!A33 -> 1099 | H7: ='42_1'!M33 -> 0.94873338 | I7: ='42_2'!A31 -> 1014 | J7: ='42_2'!M31 -> 0.96390782 | K7: 747 | L7: 0.96348934 | M7: ='48_2'!A29 -> 824 | N7: ='48_2'!M29 -> 0.97072659
A8: ='20_1'!A70 -> 4595 | B8: ='20_1'!M70 -> 0.99022902 | C8: ='37_1'!A46 -> 1394 | D8: ='37_1'!M46 -> 0.93880833 | E8: ='37_2'!A82 -> 1344 | F8: ='37_2'!M82 -> 0.96096857 | G8: ='42_1'!A34 -> 1221 | H8: ='42_1'!M34 -> 0.95401248 | I8: ='42_2'!A32 -> 1136 | J8: ='42_2'!M32 -> 0.96313233 | K8: 839 | L8: 0.962539 | M8: ='48_2'!A30 -> 916 | N8: ='48_2'!M30 -> 0.95975575
A9: ='20_1'!A71 -> 5197 | B9: ='20_1'!M71 -> 0.98823148 | C9: ='37_1'!A47 -> 1546 | D9: ='37_1'!M47 -> 0.93976682 | E9: ='37_2'!A83 -> 1496 | F9: ='37_2'!M83 -> 0.95348748 | G9: ='42_1'!A35 -> 1343 | H9: ='42_1'!M35 -> 0.95351456 | I9: ='42_2'!A33 -> 1257 | J9: ='42_2'!M33 -> 0.95805023 | K9: 931 | L9: 0.96275516 | M9: ='48_2'!A31 -> 1008 | N9: ='48_2'!M31 -> 0.96841145
A10: ='20_1'!A72 -> 5800 | B10: ='20_1'!M72 -> 0.98892856 | C10: ='37_1'!A48 -> 1698 | D10: ='37_1'!M48 -> 0.93681577 | E10: ='37_2'!A84 -> 1648 | F10: ='37_2'!M84 -> 0.95550883 | G10: ='42_1'!A36 -> 1465 | H10: ='42_1'!M36 -> 0.95354599 | I10: ='42_2'!A34 -> 1379 | J10: ='42_2'!M34 -> 0.95344634 | K10: 1023 | L10: 0.9621628 | M10: ='48_2'!A32 -> 1099 | N10: ='48_2'!M32 -> 0.96207185
A11: ='20_1'!A73 -> 6403 | B11: ='20_1'!M73 -> 0.98903891 | C11: ='37_1'!A49 -> 1850 | D11: ='37_1'!M49 -> 0.93587409 | E11: ='37_2'!A85 -> 1800 | F11: ='37_2'!M85 -> 0.95553626 | G11: ='42_1'!A37 -> 1587 | H11: ='42_1'!M37 -> 0.94990652 | I11: ='42_2'!A35 -> 1501 | J11: ='42_2'!M35 -> 0.95162954 | K11: 1115 | L11: 0.96019308 | M11: ='48_2'!A33 -> 1191 | N11: ='48_2'!M33 -> 0.96822391
A12: ='20_1'!A74 -> 7006 | B12: ='20_1'!M74 -> 0.98769534 | C12: ='37_1'!A50 -> 2002 | D12: ='37_1'!M50 -> 0.93464263 | E12: ='37_2'!A86 -> 1951 | F12: ='37_2'!M86 -> 0.9509889 | G12: ='42_1'!A38 -> 1709 | H12: ='42_1'!M38 -> 0.95202973 | I12: ='42_2'!A36 -> 1623 | J12: ='42_2'!M36 -> 0.95411775 | K12: 1207 | L12: 0.95864534 | M12: ='48_2'!A34 -> 1283 | N12: ='48_2'!M34 -> 0.96114033
A13: ='20_1'!A75 -> 7608 | B13: ='20_1'!M75 -> 0.98876881 | C13: ='37_1'!A51 -> 2153 | D13: ='37_1'!M51 -> 0.93194281 | E13: ='37_2'!A87 -> 2103 | F13: ='37_2'!M87 -> 0.95312134 | G13: ='42_1'!A39 -> 1830 | H13: ='42_1'!M39 -> 0.95379584 | I13: ='42_2'!A37 -> 1745 | J13: ='42_2'!M37 -> 0.95407389 | K13: 1299 | L13: 0.96135865 | M13: ='48_2'!A35 -> 1375 | N13: ='48_2'!M35 -> 0.96333919
... A21: ='20_1'!A83 -> 12431 | B21: ='20_1'!M83 -> 0.98480633 | C21: ='37_1'!A59 -> 3368 | D21: ='37_1'!M59 -> 0.92723823 | E21: ='37_2'!A95 -> 3318 | F21: ='37_2'!M95 -> 0.93999802 | G21: ='42_1'!A47 -> 2805 | H21: ='42_1'!M47 -> 0.94787099 | I21: ='42_2'!A45 -> 2720 | J21: ='42_2'!M45 -> 0.94990325 | K21: 2033 | L21: 0.95970463 | M21: ='48_2'!A43 -> 2110 | N21: ='48_2'!M43 -> 0.93911083
A22: ='20_1'!A84 -> 13033 | B22: ='20_1'!M84 -> 0.98472231 | C22: ='37_1'!A60 -> 3520 | D22: ='37_1'!M60 -> 0.92810439 | E22: ='37_2'!A96 -> 3470 | F22: ='37_2'!M96 -> 0.94319196 | G22: ='42_1'!A48 -> 2927 | H22: ='42_1'!M48 -> 0.94586562 | I22: ='42_2'!A46 -> 2842 | J22: ='42_2'!M46 -> 0.94291823
A23: ='20_1'!A85 -> 13636 | B23: ='20_1'!M85 -> 0.98431446 | C23: ='37_1'!A61 -> 3672 | D23: ='37_1'!M61 -> 0.92565164 | E23: ='37_2'!A97 -> 3622 | F23: ='37_2'!M97 -> 0.94475529 | G23: ='42_1'!A49 -> 3049 | H23: ='42_1'!M49 -> 0.94422328 | I23: ='42_2'!A47 -> 2963 | J23: ='42_2'!M47 -> 0.94782278
A24: ='20_1'!A86 -> 14239 | B24: ='20_1'!M86 -> 0.98338816 | C24: ='37_1'!A62 -> 3824 | D24: ='37_1'!M62 -> 0.92115376 | E24: ='37_2'!A98 -> 3773 | F24: ='37_2'!M98 -> 0.94841162 | G24: ='42_1'!A50 -> 3171 | H24: ='42_1'!M50 -> 0.94157426
A25: ='20_1'!A87 -> 14842 | B25: ='20_1'!M87 -> 0.98470258 | C25: ='37_1'!A63 -> 3976 | D25: ='37_1'!M63 -> 0.92308729 | E25: ='37_2'!A99 -> 3925 | F25: ='37_2'!M99 -> 0.9438542 | G25: ='42_1'!A51 -> 3293 | H25: ='42_1'!M51 -> 0.94763673
A26: ='20_1'!A88 -> 15444 | B26: ='20_1'!M88 -> 0.98392784 | C26: ='37_1'!A64 -> 4127 | D26: ='37_1'!M64 -> 0.92393062 | E26: ='37_2'!A100 -> 4077 | F26: ='37_2'!M100 -> 0.93895357
A27: ='20_1'!A89 -> 16047 | B27: ='20_1'!M89 -> 0.98298275 | C27: ='37_1'!A65 -> 4279 | D27: ='37_1'!M65 -> 0.91975791 | E27: ='37_2'!A101 -> 4229 | F27: ='37_2'!M101 -> 0.95030111
A28: ='20_1'!A90 -> 16650 | B28: ='20_1'!M90 -> 0.9832406 | C28: ='37_1'!A66 -> 4431 | D28: ='37_1'!M66 -> 0.91724738 | E28: ='37_2'!A102 -> 4381 | F28: ='37_2'!M102 -> 0.94248165
A29: ='20_1'!A91 -> 17253 | B29: ='20_1'!M91 -> 0.98212295 | C29: ='37_1'!A67 -> 4583 | D29: ='37_1'!M67 -> 0.92088152 | E29: ='37_2'!A103 -> 4533 | F29: ='37_2'!M103 -> 0.94670143
A30: ='20_1'!A92 -> 17856 | B30: ='20_1'!M92 -> 0.98264631 | C30: ='37_1'!A68 -> 4735 | D30: ='37_1'!M68 -> 0.92549899 | E30: ='37_2'!A104 -> 4684 | F30: ='37_2'!M104 -> 0.94440817
A31: ='20_1'!A93 -> 18458 | B31: ='20_1'!M93 -> 0.98289083 | C31: ='37_1'!A69 -> 4887 | D31: ='37_1'!M69 -> 0.91774957 | E31: ='37_2'!A105 -> 4836 | F31: ='37_2'!M105 -> 0.94184663
A32: ='20_1'!A94 -> 19061 | B32: ='20_1'!M94 -> 0.98270309 | C32: ='37_1'!A70 -> 5039 | D32: ='37_1'!M70 -> 0.9211235 | E32: ='37_2'!A106 -> 4988 | F32: ='37_2'!M106 -> 0.94360362
A33: ='20_1'!A95 -> 19664 | B33: ='20_1'!M95 -> 0.98217765 | C33: ='37_1'!A71 -> 5190 | D33: ='37_1'!M71 -> 0.91275098 | E33: ='37_2'!A107 -> 5140 | F33: ='37_2'!M107 -> 0.94425667
A34: ='20_1'!A96 -> 20267 | B34: ='20_1'!M96 -> 0.98166801 | C34: ='37_1'!A72 -> 5342 | D34: ='37_1'!M72 -> 0.90949964 | E34: ='37_2'!A108 -> 5292 | F34: ='37_2'!M108 -> 0.94264029
A35: ='20_1'!A97 -> 20869 | B35: ='20_1'!M97 -> 0.98165993 | C35: ='37_1'!A73 -> 5494 | D35: ='37_1'!M73 -> 0.91142401 | E35: ='37_2'!A109 -> 5444 | F35: ='37_2'!M109 -> 0.93622439
A36: ='20_1'!A98 -> 21472 | B36: ='20_1'!M98 -> 0.98114999 | C36: ='37_1'!A74 -> 5646 | D36: ='37_1'!M74 -> 0.91666156 | E36: ='37_2'!A110 -> 5595 | F36: ='37_2'!M110 -> 0.9381564
A37: ='20_1'!A99 -> 22075 | B37: ='20_1'!M99 -> 0.98071005 | C37: ='37_1'!A75 -> 5798 | D37: ='37_1'!M75 -> 0.92220744 | E37: ='37_2'!A111 -> 5747 | F37: ='37_2'!M111 -> 0.93694263
A38: ='20_1'!A100 -> 22678 | B38: ='20_1'!M100 -> 0.98066541 | E38: ='37_2'!A112 -> 5899 | F38: ='37_2'!M112 -> 0.94155247
A39: ='20_1'!A101 -> 23281 | B39: ='20_1'!M101 -> 0.98111191 | E39: ='37_2'!A113 -> 6051 | F39: ='37_2'!M113 -> 0.93601059
A40: ='20_1'!A102 -> 23883 | B40: ='20_1'!M102 -> 0.98032022 | E40: ='37_2'!A114 -> 6203 | F40: ='37_2'!M114 -> 0.9396867
A41: ='20_1'!A103 -> 24486 | B41: ='20_1'!M103 -> 0.9804287 | E41: ='37_2'!A115 -> 6355 | F41: ='37_2'!M115 -> 0.93759262
A42: ='20_1'!A104 -> 25089 | B42: ='20_1'!M104 -> 0.98059333 | E42: ='37_2'!A116 -> 6506 | F42: ='37_2'!M116 -> 0.94931649
A43: ='20_1'!A105 -> 25692 | B43: ='20_1'!M105 -> 0.97964744 | E43: ='37_2'!A117 -> 6658 | F43: ='37_2'!M117 -> 0.94161813
A44: ='20_1'!A106 -> 26295 | B44: ='20_1'!M106 -> 0.97935713 | E44: ='37_2'!A118 -> 6810 | F44: ='37_2'!M118 -> 0.94237601
A45: ='20_1'!A107 -> 26897 | B45: ='20_1'!M107 -> 0.97994883 | E45: ='37_2'!A119 -> 6962 | F45: ='37_2'!M119 -> 0.9465185
A46: ='20_1'!A108 -> 27500 | B46: ='20_1'!M108 -> 0.98019136 | E46: ='37_2'!A120 -> 7114 | F46: ='37_2'!M120 -> 0.93427731
A47: ='20_1'!A109 -> 28103 | B47: ='20_1'!M109 -> 0.98021518 | E47: ='37_2'!A121 -> 7266 | F47: ='37_2'!M121 -> 0.94252698
...

Sheet all_8ppm
A1: time_1 | B1: 20_1 | C1: time_2 | D1: 37_1 | E1: time_3 | F1: 37_2 | G1: time_4 | H1: 42_1 | I1: time_5 | J1: 42_2 | K1: time_6 | L1: 48_1 | M1: time_7 | N1: 48_2
A2: ='20_1'!A64 -> 978 | B2: ='20_1'!N2 -> 0.45241713 | C2: ='37_1'!A40 -> 483 | D2: ='37_1'!N2 -> 0.40702453 | E2: ='37_2'!A76 -> 433 | F2: ='37_2'!N2 -> 0.40696584 | G2: ='42_1'!A28 -> 490 | H2: ='42_1'!N2 -> 0.39395294 | I2: ='42_2'!A26 -> 404 | J2: ='42_2'!N2 -> 0.40251848 | K2: 288 | L2: ='48_1'!N2 -> 0.39099765 | M2: ='48_2'!A24 -> 365 | N2: ='48_2'!N2 -> 0.38402977
A3: ='20_1'!A65 -> 1581 | B3: ='20_1'!N3 -> 0.44914031 | C3: ='37_1'!A41 -> 635 | D3: ='37_1'!N3 -> 0.40499534 | E3: ='37_2'!A77 -> 585 | F3: ='37_2'!N3 -> 0.40484289 | G3: ='42_1'!A29 -> 612 | H3: ='42_1'!N3 -> 0.39417373 | I3: ='42_2'!A27 -> 526 | J3: ='42_2'!N3 -> 0.39558975 | K3: 380 | L3: ='48_1'!N3 -> 0.39331163 | M3: ='48_2'!A25 -> 456 | N3: ='48_2'!N3 -> 0.38152247
A4: ='20_1'!A66 -> 2183 | B4: ='20_1'!N4 -> 0.44560576 | C4: ='37_1'!A42 -> 787 | D4: ='37_1'!N4 -> 0.40118323 | E4: ='37_2'!A78 -> 737 | F4: ='37_2'!N4 -> 0.40570542 | G4: ='42_1'!A30 -> 734 | H4: ='42_1'!N4 -> 0.39374994 | I4: ='42_2'!A28 -> 648 | J4: ='42_2'!N4 -> 0.39704214 | K4: 472 | L4: ='48_1'!N4 -> 0.38789671 | M4: ='48_2'!A26 -> 548 | N4: ='48_2'!N4 -> 0.38211404
A5: ='20_1'!A67 -> 2786 | B5: ='20_1'!N5 -> 0.44472985 | C5: ='37_1'!A43 -> 939 | D5: ='37_1'!N5 -> 0.40176116 | E5: ='37_2'!A79 -> 889 | F5: ='37_2'!N5 -> 0.40584868 | G5: ='42_1'!A31 -> 856 | H5: ='42_1'!N5 -> 0.39221764 | I5: ='42_2'!A29 -> 770 | J5: ='42_2'!N5 -> 0.39917337 | K5: 564 | L5: ='48_1'!N5 -> 0.38667772 | M5: ='48_2'!A27 -> 640 | N5: ='48_2'!N5 -> 0.38112262
A6: ='20_1'!A68 -> 3389 | B6: ='20_1'!N6 -> 0.44137365 | C6: ='37_1'!A44 -> 1090 | D6: ='37_1'!N6 -> 0.40029775 | E6: ='37_2'!A80 -> 1040 | F6: ='37_2'!N6 -> 0.40114697 | G6: ='42_1'!A32 -> 977 | H6: ='42_1'!N6 -> 0.38853682 | I6: ='42_2'!A30 -> 892 | J6: ='42_2'!N6 -> 0.39353238 | K6: 656 | L6: ='48_1'!N6 -> 0.38317047 | M6: ='48_2'!A28 -> 732 | N6: ='48_2'!N6 -> 0.37893503
A7: ='20_1'!A69 -> 3992 | B7: ='20_1'!N7 -> 0.44035207 | C7: ='37_1'!A45 -> 1242 | D7: ='37_1'!N7 -> 0.3964206 | E7: ='37_2'!A81 -> 1192 | F7: ='37_2'!N7 -> 0.40167585 | G7: ='42_1'!A33 -> 1099 | H7: ='42_1'!N7 -> 0.38993056 | I7: ='42_2'!A31 -> 1014 | J7: ='42_2'!N7 -> 0.39216215 | K7: 747 | L7: ='48_1'!N7 -> 0.38182526 | M7: ='48_2'!A29 -> 824 | N7: ='48_2'!N7 -> 0.3809757
A8: ='20_1'!A70 -> 4595 | B8: ='20_1'!N8 -> 0.43704297 | C8: ='37_1'!A46 -> 1394 | D8: ='37_1'!N8 -> 0.39583004 | E8: ='37_2'!A82 -> 1344 | F8: ='37_2'!N8 -> 0.40081958 | G8: ='42_1'!A34 -> 1221 | H8: ='42_1'!N8 -> 0.38995525 | I8: ='42_2'!A32 -> 1136 | J8: ='42_2'!N8 -> 0.391257 | K8: 839 | L8: ='48_1'!N8 -> 0.38194246 | M8: ='48_2'!A30 -> 916 | N8: ='48_2'!N8 -> 0.38359386
A9: ='20_1'!A71 -> 5197 | B9: ='20_1'!N9 -> 0.43689496 | C9: ='37_1'!A47 -> 1546 | D9: ='37_1'!N9 -> 0.39418815 | E9: ='37_2'!A83 -> 1496 | F9: ='37_2'!N9 -> 0.39876706 | G9: ='42_1'!A35 -> 1343 | H9: ='42_1'!N9 -> 0.38687123 | I9: ='42_2'!A33 -> 1257 | J9: ='42_2'!N9 -> 0.39228799 | K9: 931 | L9: ='48_1'!N9 -> 0.38210815 | M9: ='48_2'!A31 -> 1008 | N9: ='48_2'!N9 -> 0.38061822
A10: ='20_1'!A72 -> 5800 | B10: ='20_1'!N10 -> 0.4374159 | C10: ='37_1'!A48 -> 1698 | D10: ='37_1'!N10 -> 0.39425703 | E10: ='37_2'!A84 -> 1648 | F10: ='37_2'!N10 -> 0.39719489 | G10: ='42_1'!A36 -> 1465 | H10: ='42_1'!N10 -> 0.38693491 | I10: ='42_2'!A34 -> 1379 | J10: ='42_2'!N10 -> 0.3931304 | K10: 1023 | L10: ='48_1'!N10 -> 0.38310848 | M10: ='48_2'!A32 -> 1099 | N10: ='48_2'!N10 -> 0.37609415
A11: ='20_1'!A73 -> 6403 | B11: ='20_1'!N11 -> 0.43436564 | C11: ='37_1'!A49 -> 1850 | D11: ='37_1'!N11 -> 0.39470535 | E11: ='37_2'!A85 -> 1800 | F11: ='37_2'!N11 -> 0.39580107 | G11: ='42_1'!A37 -> 1587 | H11: ='42_1'!N11 -> 0.38391075 | I11: ='42_2'!A35 -> 1501 | J11: ='42_2'!N11 -> 0.39025278 | K11: 1115 | L11: ='48_1'!N11 -> 0.37971723 | M11: ='48_2'!A33 -> 1191 | N11: ='48_2'!N11 -> 0.37381961
A12: ='20_1'!A74 -> 7006 | B12: ='20_1'!N12 -> 0.43344793 | C12: ='37_1'!A50 -> 2002 | D12: ='37_1'!N12 -> 0.39167025 | E12: ='37_2'!A86 -> 1951 | F12: ='37_2'!N12 -> 0.39678402 | G12: ='42_1'!A38 -> 1709 | H12: ='42_1'!N12 -> 0.38561799 | I12: ='42_2'!A36 -> 1623 | J12: ='42_2'!N12 -> 0.38737911 | K12: 1207 | L12: ='48_1'!N12 -> 0.37678051 | M12: ='48_2'!A34 -> 1283 | N12: ='48_2'!N12 -> 0.38267245
A13: ='20_1'!A75 -> 7608 | B13: ='20_1'!N13 -> 0.43722163 | C13: ='37_1'!A51 -> 2153 | D13: ='37_1'!N13 -> 0.39154766 | E13: ='37_2'!A87 -> 2103 | F13: ='37_2'!N13 -> 0.39572356 | G13: ='42_1'!A39 -> 1830 | H13: ='42_1'!N13 -> 0.38647548 | I13: ='42_2'!A37 -> 1745 | J13: ='42_2'!N13 -> 0.38824951 | K13: 1299 | L13: ='48_1'!N13 -> 0.38069347 | M13: ='48_2'!A35 -> 1375 | N13: ='48_2'!N13 -> 0.37603551
... A21: ='20_1'!A83 -> 12431 | B21: ='20_1'!N21 -> 0.4294081 | C21: ='37_1'!A59 -> 3368 | D21: ='37_1'!N21 -> 0.38811718 | E21: ='37_2'!A95 -> 3318 | F21: ='37_2'!N21 -> 0.39051427 | G21: ='42_1'!A47 -> 2805 | H21: ='42_1'!N21 -> 0.38486502 | I21: ='42_2'!A45 -> 2720 | J21: ='42_2'!N21 -> 0.38623051 | K21: 2033 | L21: ='48_1'!N21 -> 0.37762076 | M21: ='48_2'!A43 -> 2110 | N21: ='48_2'!N21 -> 0.36826135
A22: ='20_1'!A84 -> 13033 | B22: ='20_1'!N22 -> 0.42879846 | C22: ='37_1'!A60 -> 3520 | D22: ='37_1'!N22 -> 0.388258 | E22: ='37_2'!A96 -> 3470 | F22: ='37_2'!N22 -> 0.39254591 | G22: ='42_1'!A48 -> 2927 | H22: ='42_1'!N22 -> 0.38383907 | I22: ='42_2'!A46 -> 2842 | J22: ='42_2'!N22 -> 0.38704676
A23: ='20_1'!A85 -> 13636 | B23: ='20_1'!N23 -> 0.43206787 | C23: ='37_1'!A61 -> 3672 | D23: ='37_1'!N23 -> 0.38666788 | E23: ='37_2'!A97 -> 3622 | F23: ='37_2'!N23 -> 0.3930158 | G23: ='42_1'!A49 -> 3049 | H23: ='42_1'!N23 -> 0.38453599 | I23: ='42_2'!A47 -> 2963 | J23: ='42_2'!N23 -> 0.38719391
A24: ='20_1'!A86 -> 14239 | B24: ='20_1'!N24 -> 0.42842362 | C24: ='37_1'!A62 -> 3824 | D24: ='37_1'!N24 -> 0.38644069 | E24: ='37_2'!A98 -> 3773 | F24: ='37_2'!N24 -> 0.39008759 | G24: ='42_1'!A50 -> 3171 | H24: ='42_1'!N24 -> 0.38113931
A25: ='20_1'!A87 -> 14842 | B25: ='20_1'!N25 -> 0.4220951 | C25: ='37_1'!A63 -> 3976 | D25: ='37_1'!N25 -> 0.3881273 | E25: ='37_2'!A99 -> 3925 | F25: ='37_2'!N25 -> 0.39373592 | G25: ='42_1'!A51 -> 3293 | H25: ='42_1'!N25 -> 0.38510777
A26: ='20_1'!A88 -> 15444 | B26: ='20_1'!N26 -> 0.42675436 | C26: ='37_1'!A64 -> 4127 | D26: ='37_1'!N26 -> 0.38778371 | E26: ='37_2'!A100 -> 4077 | F26: ='37_2'!N26 -> 0.38999251
A27: ='20_1'!A89 -> 16047 | B27: ='20_1'!N27 -> 0.42589782 | C27: ='37_1'!A65 -> 4279 | D27: ='37_1'!N27 -> 0.38584244 | E27: ='37_2'!A101 -> 4229 | F27: ='37_2'!N27 -> 0.39345675
A28: ='20_1'!A90 -> 16650 | B28: ='20_1'!N28 -> 0.42513101 | C28: ='37_1'!A66 -> 4431 | D28: ='37_1'!N28 -> 0.38680977 | E28: ='37_2'!A102 -> 4381 | F28: ='37_2'!N28 -> 0.39112292
A29: ='20_1'!A91 -> 17253 | B29: ='20_1'!N29 -> 0.42264992 | C29: ='37_1'!A67 -> 4583 | D29: ='37_1'!N29 -> 0.38728589 | E29: ='37_2'!A103 -> 4533 | F29: ='37_2'!N29 -> 0.3905477
A30: ='20_1'!A92 -> 17856 | B30: ='20_1'!N30 -> 0.42361549 | C30: ='37_1'!A68 -> 4735 | D30: ='37_1'!N30 -> 0.38592841 | E30: ='37_2'!A104 -> 4684 | F30: ='37_2'!N30 -> 0.38869496
A31: ='20_1'!A93 -> 18458 | B31: ='20_1'!N31 -> 0.4236736 | C31: ='37_1'!A69 -> 4887 | D31: ='37_1'!N31 -> 0.38626225 | E31: ='37_2'!A105 -> 4836 | F31: ='37_2'!N31 -> 0.39089807
A32: ='20_1'!A94 -> 19061 | B32: ='20_1'!N32 -> 0.42289389 | C32: ='37_1'!A70 -> 5039 | D32: ='37_1'!N32 -> 0.38635782 | E32: ='37_2'!A106 -> 4988 | F32: ='37_2'!N32 -> 0.39004781
A33: ='20_1'!A95 -> 19664 | B33: ='20_1'!N33 -> 0.42312584 | C33: ='37_1'!A71 -> 5190 | D33: ='37_1'!N33 -> 0.38663357 | E33: ='37_2'!A107 -> 5140 | F33: ='37_2'!N33 -> 0.3908243
A34: ='20_1'!A96 -> 20267 | B34: ='20_1'!N34 -> 0.42160686 | C34: ='37_1'!A72 -> 5342 | D34: ='37_1'!N34 -> 0.38547551 | E34: ='37_2'!A108 -> 5292 | F34: ='37_2'!N34 -> 0.39069119
A35: ='20_1'!A97 -> 20869 | B35: ='20_1'!N35 -> 0.42242836 | C35: ='37_1'!A73 -> 5494 | D35: ='37_1'!N35 -> 0.38663332 | E35: ='37_2'!A109 -> 5444 | F35: ='37_2'!N35 -> 0.39052658
A36: ='20_1'!A98 -> 21472 | B36: ='20_1'!N36 -> 0.42229942 | C36: ='37_1'!A74 -> 5646 | D36: ='37_1'!N36 -> 0.38641804 | E36: ='37_2'!A110 -> 5595 | F36: ='37_2'!N36 -> 0.39125311
A37: ='20_1'!A99 -> 22075 | B37: ='20_1'!N37 -> 0.4192117 | C37: ='37_1'!A75 -> 5798 | D37: ='37_1'!N37 -> 0.38756501 | E37: ='37_2'!A111 -> 5747 | F37: ='37_2'!N37 -> 0.39070552
A38: ='20_1'!A100 -> 22678 | B38: ='20_1'!N38 -> 0.41684295 | E38: ='37_2'!A112 -> 5899 | F38: ='37_2'!N38 -> 0.3883896
A39: ='20_1'!A101 -> 23281 | B39: ='20_1'!N39 -> 0.41981693 | E39: ='37_2'!A113 -> 6051 | F39: ='37_2'!N39 -> 0.39327029
A40: ='20_1'!A102 -> 23883 | B40: ='20_1'!N40 -> 0.42130636 | E40: ='37_2'!A114 -> 6203 | F40: ='37_2'!N40 -> 0.39090324
A41: ='20_1'!A103 -> 24486 | B41: ='20_1'!N41 -> 0.4182898 | E41: ='37_2'!A115 -> 6355 | F41: ='37_2'!N41 -> 0.38912172
A42: ='20_1'!A104 -> 25089 | B42: ='20_1'!N42 -> 0.42109802 | E42: ='37_2'!A116 -> 6506 | F42: ='37_2'!N42 -> 0.39034388
A43: ='20_1'!A105 -> 25692 | B43: ='20_1'!N43 -> 0.42082636 | E43: ='37_2'!A117 -> 6658 | F43: ='37_2'!N43 -> 0.39253543
A44: ='20_1'!A106 -> 26295 | B44: ='20_1'!N44 -> 0.4230165 | E44: ='37_2'!A118 -> 6810 | F44: ='37_2'!N44 -> 0.3901435
A45: ='20_1'!A107 -> 26897 | B45: ='20_1'!N45 -> 0.42293002 | E45: ='37_2'!A119 -> 6962 | F45: ='37_2'!N45 -> 0.38745072
A46: ='20_1'!A108 -> 27500 | B46: ='20_1'!N46 -> 0.42095887 | E46: ='37_2'!A120 -> 7114 | F46: ='37_2'!N46 -> 0.38726716
A47: ='20_1'!A109 -> 28103 | B47: ='20_1'!N47 -> 0.42284298 | E47: ='37_2'!A121 -> 7266 | F47: ='37_2'!N47 -> 0.39047947
...

Sheet 20_1
A1: ARR_DATA(I) | B1: Integral(9.534,9.479) | C1: Integral(8.554,8.516) | D1: Integral(8.519,8.453) | E1: Integral(8.444,8.300) | F1: Integral(8.249,8.224) | G1: Integral(8.214,8.157) | H1: Integral(8.153,7.970) | I1: Integral(7.932,7.873) | J1: Integral(8.292,8.248) | L1: SUM | M1: f_dec_1 | N1: f_dec_2
A2: 978 | B2: 0.554533 | C2: 229.305 | D2: 242.121 | E2: 41173.5 | F2: 215.439 | G2: 337.572 | H2: 35034.6 | I2: 228.227 | J2: -22.6069 | L2: =SUM(B2:J2) -> 77438.712 | M2: =E2/L2 -> 0.53169144 | N2: =H2/L2 -> 0.45241713
A3: 1581 | B3: 12.8803 | C3: 200.177 | D3: 333.089 | E3: 40189 | F3: 210.776 | G3: 180.057 | H3: 33687.5 | I3: 214.571 | J3: -23.6497 | L3: =SUM(B3:J3) -> 75004.401 | M3: =E3/L3 -> 0.53582189 | N3: =H3/L3 -> 0.44914031
A4: 2183 | B4: 15.7947 | C4: 244.292 | D4: 543.628 | E4: 39745.1 | F4: 187.427 | G4: 162.732 | H4: 33022.7 | I4: 200.477 | J4: -14.7151 | L4: =SUM(B4:J4) -> 74107.436 | M4: =E4/L4 -> 0.5363173 | N4: =H4/L4 -> 0.44560576
A5: 2786 | B5: 34.9987 | C5: 209.313 | D5: 566.255 | E5: 39185.1 | F5: 217.537 | G5: 156.963 | H5: 32464.8 | I5: 159.899 | J5: 4.05748 | L5: =SUM(B5:J5) -> 72998.923 | M5: =E5/L5 -> 0.53679011 | N5: =H5/L5 -> 0.44472985
A6: 3389 | B6: 33.1914 | C6: 269.194 | D6: 899.859 | E6: 38988.9 | F6: 203.483 | G6: 274.293 | H6: 32289.5 | I6: 199.471 | J6: -1.05412 | L6: =SUM(B6:J6) -> 73156.837 | M6: =E6/L6 -> 0.5329495 | N6: =H6/L6 -> 0.44137365
A7: 3992 | B7: 52.2919 | C7: 255.796 | D7: 953.006 | E7: 38567.1 | F7: 186.99 | G7: 265.773 | H7: 31828.7 | I7: 173.995 | J7: -3.53282 | L7: =SUM(B7:J7) -> 72280.119 | M7: =E7/L7 -> 0.53357826 | N7: =H7/L7 -> 0.44035207
A8: 4595 | B8: 51.8539 | C8: 298.128 | D8: 1126.37 | E8: 38386.8 | F8: 232.989 | G8: 307.044 | H8: 31524 | I8: 187.757 | J8: 15.2647 | L8: =SUM(B8:J8) -> 72130.207 | M8: =E8/L8 -> 0.53218758 | N8: =H8/L8 -> 0.43704297
A9: 5197 | B9: 64.6254 | C9: 279.291 | D9: 1164.49 | E9: 37975.7 | F9: 215.43 | G9: 286.643 | H9: 31152.4 | I9: 156.432 | J9: 9.08391 | L9: =SUM(B9:J9) -> 71304.095 | M9: =E9/L9 -> 0.53258792 | N9: =H9/L9 -> 0.43689496
A10: 5800 | B10: 47.4213 | C10: 242.355 | D10: 1117.94 | E10: 37356.1 | F10: 182.316 | G10: 104.684 | H10: 30489.7 | I10: 134.447 | J10: 29.1791 | L10: =SUM(B10:J10) -> 69704.142 | M10: =E10/L10 -> 0.53592367 | N10: =H10/L10 -> 0.4374159
A11: 6403 | B11: 55.581 | C11: 293.686 | D11: 1305.08 | E11: 37505.2 | F11: 187.893 | G11: 202.402 | H11: 30513.9 | I11: 171.871 | J11: 13.7283 | L11: =SUM(B11:J11) -> 70249.341 | M11: =E11/L11 -> 0.53388686 | N11: =H11/L11 -> 0.43436564
A12: 7006 | B12: 99.6521 | C12: 302.538 | D12: 1392.64 | E12: 37266.9 | F12: 200.707 | G12: 206.607 | H12: 30321.5 | I12: 140.883 | J12: 22.7654 | L12: =SUM(B12:J12) -> 69954.193 | M12: =E12/L12 -> 0.5327329 | N12: =H12/L12 -> 0.43344793
A13: 7608 | B13: 133.729 | C13: 190.221 | D13: 1091.61 | E13: 36351.1 | F13: 159.292 | G13: -3.65243 | H13: 29557.8 | I13: 108.106 | J13: 15.4952 | L13: =SUM(B13:J13) -> 67603.701 | M13: =E13/L13 -> 0.53770873 | N13: =H13/L13 -> 0.43722163
... A61: 36542 | B61: 194.26 | C61: 329.722 | D61: 2109.29 | E61: 36422.9 | F61: 186.465 | G61: 47.0712 | H61: 28697.7 | I61: 108.906 | J61: 9.88374 | L61: =SUM(B61:J61) -> 68106.198 | M61: =E61/L61 -> 0.53479567 | N61: =H61/L61 -> 0.42136694
A63: ARR_DATA(I) | B63: Integral(6.773,6.679) | C63: Integral(6.100,6.053) | D63: Integral(6.005,5.974) | E63: Integral(5.968,5.875) | F63: Integral(5.836,5.773) | M63: f_dec_3
A64: 978 | B64: 3026.99 | C64: 44.1207 | D64: 53.345 | E64: 40030.9 | F64: 61.5662 | L64: =SUM(B64:J64) -> 43216.922 | M64: =E64/L64 -> 0.92627837
A65: 1581 | B65: 2528.41 | C65: 36.1039 | D65: 128.99 | E65: 38600.3 | F65: 31.9745 | L65: =SUM(B65:J65) -> 41325.778 | M65: =E65/L65 -> 0.93404895
A66: 2183 | B66: 2096.12 | C66: 27.3309 | D66: 66.7972 | E66: 36991.6 | F66: 40.0317 | L66: =SUM(B66:J66) -> 39221.88 | M66: =E66/L66 -> 0.94313685
A67: 2786 | B67: 164.608 | C67: 32.3605 | D67: 97.7181 | E67: 35881.9 | F67: 38.4485 | L67: =SUM(B67:J67) -> 36215.035 | M67: =E67/L67 -> 0.99080119
A68: 3389 | B68: 169.162 | C68: 38.7079 | D68: 128.661 | E68: 34743.3 | F68: 27.4945 | L68: =SUM(B68:J68) -> 35107.325 | M68: =E68/L68 -> 0.98963107
A69: 3992 | B69: 177.172 | C69: 34.6518 | D69: 130.545 | E69: 33750.8 | F69: 14.9268 | L69: =SUM(B69:J69) -> 34108.096 | M69: =E69/L69 -> 0.98952461
A70: 4595 | B70: 158.521 | C70: 22.6357 | D70: 145.082 | E70: 33081.9 | F70: 0.193277 | L70: =SUM(B70:J70) -> 33408.332 | M70: =E70/L70 -> 0.99022902
A71: 5197 | B71: 153.503 | C71: 34.9435 | D71: 173.263 | E71: 32393.9 | F71: 24.0588 | L71: =SUM(B71:J71) -> 32779.668 | M71: =E71/L71 -> 0.98823148
A72: 5800 | B72: 155.272 | C72: 33.0077 | D72: 172.797 | E72: 31814 | F72: -4.90652 | L72: =SUM(B72:J72) -> 32170.17 | M72: =E72/L72 -> 0.98892856
A73: 6403 | B73: 160.399 | C73: 15.2669 | D73: 171.075 | E73: 31375.8 | F73: 0.983509 | L73: =SUM(B73:J73) -> 31723.524 | M73: =E73/L73 -> 0.98903891
A74: 7006 | B74: 174.25 | C74: 21.8564 | D74: 196.866 | E74: 30919.6 | F74: -7.77761 | L74: =SUM(B74:J74) -> 31304.795 | M74: =E74/L74 -> 0.98769534
A75: 7608 | B75: 152.032 | C75: 29.0687 | D75: 189.125 | E75: 30567.5 | F75: -23.0166 | L75: =SUM(B75:J75) -> 30914.709 | M75: =E75/L75 -> 0.98876881
... A123: 36542 | B123: 137.349 | C123: 63.3188 | D123: 403.643 | E123: 29143 | F123: -72.8233 | L123: =SUM(B123:J123) -> 29674.487 | M123: =E123/L123 -> 0.98208941
A125: ARR_DATA(I) | B125: Integral(3.848,3.833)
A126: 978 | B126: 412210
A127: 1581 | B127: 357042
A128: 2183 | B128: 316332
A129: 2786 | B129: 281792
A130: 3389 | B130: 250137
A131: 3992 | B131: 223041
A132: 4595 | B132: 203248
A133: 5197 | B133: 184321
A134: 5800 | B134: 167469
A135: 6403 | B135: 152467
A136: 7006 | B136: 140305
...

Sheet 37_1
A1: ARR_DATA(I) | B1: Integral(9.713,9.651) | C1: Integral(8.723,8.695) | D1: Integral(8.691,8.655) | E1: Integral(8.553,8.503) | F1: Integral(8.471,8.447) | G1: Integral(8.447,8.424) | H1: Integral(8.366,8.336) | I1: Integral(8.288,8.226) | J1: Integral(8.113,8.084) | L1: SUM | M1: f_dec_1 | N1: f_dec_2
A2: 483 | B2: 8.8682 | C2: 56.7132 | D2: 107.682 | E2: 8011.13 | F2: 1.21467 | G2: 35.9428 | H2: 40.1228 | I2: 5688.82 | J2: 26.1086 | L2: =SUM(B2:J2) -> 13976.602 | M2: =E2/L2 -> 0.57318151 | N2: =I2/L2 -> 0.40702453
A3: 635 | B3: 17.0913 | C3: 49.0417 | D3: 131.766 | E3: 7955.31 | F3: -2.19798 | G3: 37.7191 | H3: 44.6553 | I3: 5630.42 | J3: 38.626 | L3: =SUM(B3:J3) -> 13902.431 | M3: =E3/L3 -> 0.57222437 | N3: =I3/L3 -> 0.40499534
A4: 787 | B4: 14.5318 | C4: 68.5656 | D4: 178.054 | E4: 7921.09 | F4: -0.848903 | G4: 51.004 | H4: 45.3846 | I4: 5570.5 | J4: 36.8954 | L4: =SUM(B4:J4) -> 13885.176 | M4: =E4/L4 -> 0.57047096 | N4: =I4/L4 -> 0.40118323
A5: 939 | B5: 22.4607 | C5: 60.7974 | D5: 190.895 | E5: 7909.24 | F5: -4.06062 | G5: 50.3581 | H5: 59.3752 | I5: 5598.46 | J5: 47.2707 | L5: =SUM(B5:J5) -> 13934.796 | M5: =E5/L5 -> 0.5675892 | N5: =I5/L5 -> 0.40176116
A6: 1090 | B6: 21.5374 | C6: 58.4772 | D6: 209.929 | E6: 7905.67 | F6: 5.22608 | G6: 50.5846 | H6: 47.7482 | I6: 5564.93 | J6: 37.8742 | L6: =SUM(B6:J6) -> 13901.977 | M6: =E6/L6 -> 0.56867237 | N6: =I6/L6 -> 0.40029775
A7: 1242 | B7: 29.988 | C7: 72.2626 | D7: 232.912 | E7: 7905.97 | F7: 8.49043 | G7: 53.5883 | H7: 52.3888 | I7: 5516.25 | J7: 43.2945 | L7: =SUM(B7:J7) -> 13915.145 | M7: =E7/L7 -> 0.56815579 | N7: =I7/L7 -> 0.3964206
A8: 1394 | B8: 36.9324 | C8: 68.6077 | D8: 243.632 | E8: 7924.23 | F8: -2.47568 | G8: 50.1047 | H8: 51.9482 | I8: 5509.74 | J8: 36.7397 | L8: =SUM(B8:J8) -> 13919.459 | M8: =E8/L8 -> 0.56929152 | N8: =I8/L8 -> 0.39583004
A9: 1546 | B9: 36.8624 | C9: 59.5772 | D9: 262.045 | E9: 7902.06 | F9: 8.66703 | G9: 56.1716 | H9: 35.1583 | I9: 5464.7 | J9: 37.9353 | L9: =SUM(B9:J9) -> 13863.177 | M9: =E9/L9 -> 0.57000355 | N9: =I9/L9 -> 0.39418815
A10: 1698 | B10: 22.202 | C10: 72.2344 | D10: 268.311 | E10: 7843.79 | F10: 7.96922 | G10: 57.1137 | H10: 31.0603 | I10: 5431.49 | J10: 42.3497 | L10: =SUM(B10:J10) -> 13776.52 | M10: =E10/L10 -> 0.5693593 | N10: =I10/L10 -> 0.39425703
A11: 1850 | B11: 22.6191 | C11: 63.0977 | D11: 290.544 | E11: 7886.43 | F11: -10.9883 | G11: 43.586 | H11: 40.1543 | I11: 5464.11 | J11: 43.9635 | L11: =SUM(B11:J11) -> 13843.516 | M11: =E11/L11 -> 0.56968402 | N11: =I11/L11 -> 0.39470535
A12: 2002 | B12: 40.7032 | C12: 69.4243 | D12: 300.729 | E12: 7875.18 | F12: 16.164 | G12: 65.8211 | H12: 46.1013 | I12: 5445.09 | J12: 43.0172 | L12: =SUM(B12:J12) -> 13902.23 | M12: =E12/L12 -> 0.56646883 | N12: =I12/L12 -> 0.39167025
A13: 2153 | B13: 25.5986 | C13: 60.751 | D13: 302.534 | E13: 7853.85 | F13: 11.3078 | G13: 56.0206 | H13: 48.9808 | I13: 5405.39 | J13: 40.7575 | L13: =SUM(B13:J13) -> 13805.19 | M13: =E13/L13 -> 0.56890559 | N13: =I13/L13 -> 0.39154766
... A37: 5798 | B37: 46.4761 | C37: 83.2601 | D37: 374.546 | E37: 7884.47 | F37: 3.24074 | G37: 49.033 | H37: 33.8334 | I37: 5386.28 | J37: 36.6064 | L37: =SUM(B37:J37) -> 13897.746 | M37: =E37/L37 -> 0.56732006 | N37: =I37/L37 -> 0.38756501
A39: ARR_DATA(I) | B39: Integral(6.907,6.778) | C39: Integral(6.341,6.231) | D39: Integral(6.192,6.153) | E39: Integral(6.152,6.085) | F39: Integral(6.011,5.958) | M39: f_dec_3
A40: 483 | B40: 48.1838 | C40: 50.8848 | D40: 135.257 | E40: 7995.1 | F40: 31.2364 | L40: =SUM(B40:J40) -> 8260.662 | M40: =E40/L40 -> 0.96785221
A41: 635 | B41: 49.3182 | C41: 47.1938 | D41: 219.365 | E41: 7947.45 | F41: 43.9772 | L41: =SUM(B41:J41) -> 8307.3042 | M41: =E41/L41 -> 0.95668219
A42: 787 | B42: 38.2494 | C42: 58.3251 | D42: 246.355 | E42: 7884.99 | F42: 42.8223 | L42: =SUM(B42:J42) -> 8270.7418 | M42: =E42/L42 -> 0.95335947
A43: 939 | B43: 35.2287 | C43: 59.6149 | D43: 307.417 | E43: 7824.04 | F43: 34.5167 | L43: =SUM(B43:J43) -> 8260.8173 | M43: =E43/L43 -> 0.94712662
A44: 1090 | B44: 55.5217 | C44: 50.8291 | D44: 287.667 | E44: 7816.44 | F44: 37.3438 | L44: =SUM(B44:J44) -> 8247.8016 | M44: =E44/L44 -> 0.94769981
A45: 1242 | B45: 46.9795 | C45: 87.2207 | D45: 304.634 | E45: 7788.58 | F45: 37.8162 | L45: =SUM(B45:J45) -> 8265.2304 | M45: =E45/L45 -> 0.94233066
A46: 1394 | B46: 42.2471 | C46: 88.4632 | D46: 340.191 | E46: 7773.87 | F46: 35.8007 | L46: =SUM(B46:J46) -> 8280.572 | M46: =E46/L46 -> 0.93880833
A47: 1546 | B47: 37.2129 | C47: 69.1062 | D47: 356.166 | E47: 7729.35 | F47: 32.9179 | L47: =SUM(B47:J47) -> 8224.753 | M47: =E47/L47 -> 0.93976682
A48: 1698 | B48: 43.2789 | C48: 81.3293 | D48: 362.666 | E48: 7729.23 | F48: 34.0294 | L48: =SUM(B48:J48) -> 8250.5336 | M48: =E48/L48 -> 0.93681577
A49: 1850 | B49: 59.8845 | C49: 61.8023 | D49: 384.48 | E49: 7696.66 | F49: 21.2068 | L49: =SUM(B49:J49) -> 8224.0336 | M49: =E49/L49 -> 0.93587409
A50: 2002 | B50: 32.264 | C50: 74.139 | D50: 395.704 | E50: 7710.01 | F50: 37.0359 | L50: =SUM(B50:J50) -> 8249.1529 | M50: =E50/L50 -> 0.93464263
A51: 2153 | B51: 37.5658 | C51: 72.3809 | D51: 414.853 | E51: 7682 | F51: 36.1954 | L51: =SUM(B51:J51) -> 8242.9951 | M51: =E51/L51 -> 0.93194281
... A75: 5798 | B75: 49.6137 | C75: 109.12 | D75: 451.815 | E75: 7657.14 | F75: 35.3673 | L75: =SUM(B75:J75) -> 8303.056 | M75: =E75/L75 -> 0.92220744
A77: ARR_DATA(I) | B77: Integral(4.056,4.016)
A78: 483 | B78: 58755.1
A79: 635 | B79: 51962.2
A80: 787 | B80: 45701.3
A81: 939 | B81: 40215.6
A82: 1090 | B82: 35441.5
A83: 1242 | B83: 31231.9
A84: 1394 | B84: 27398.1
A85: 1546 | B85: 24018.3
A86: 1698 | B86: 21219.3
A87: 1850 | B87: 18729.9
A88: 2002 | B88: 16432.1
...

Sheet 37_2
A1: ARR_DATA(I) | B1: Integral(9.702,9.670) | C1: Integral(8.728,8.695) | D1: Integral(8.695,8.653) | E1: Integral(8.555,8.489) | F1: Integral(8.469,8.459) | G1: Integral(8.450,8.419) | H1: Integral(8.361,8.342) | I1: Integral(8.289,8.233) | J1: Integral(8.110,8.084) | L1: SUM | M1: f_dec_1 | N1: f_dec_2
A2: 433 | B2: 4.24141 | C2: 42.7431 | D2: 88.0091 | E2: 7539.95 | F2: 0.0591018 | G2: 33.2053 | H2: 36.5108 | I2: 5343.49 | J2: 41.8612 | L2: =SUM(B2:J2) -> 13130.07 | M2: =E2/L2 -> 0.57425056 | N2: =I2/L2 -> 0.40696584
A3: 585 | B3: 3.82467 | C3: 48.8946 | D3: 111.314 | E3: 7388.24 | F3: 3.82827 | G3: 45.7051 | H3: 36.2784 | I3: 5222.02 | J3: 38.7752 | L3: =SUM(B3:J3) -> 12898.88 | M3: =E3/L3 -> 0.5727815 | N3: =I3/L3 -> 0.40484289
A4: 737 | B4: 3.80918 | C4: 41.7986 | D4: 128.589 | E4: 7410.83 | F4: -3.04235 | G4: 45.3972 | H4: 33.6689 | I4: 5258.94 | J4: 42.4688 | L4: =SUM(B4:J4) -> 12962.459 | M4: =E4/L4 -> 0.57171481 | N4: =I4/L4 -> 0.40570542
A5: 889 | B5: 2.51489 | C5: 57.5147 | D5: 156.264 | E5: 7303.26 | F5: -3.31813 | G5: 55.6157 | H5: 39.5774 | I5: 5226.93 | J5: 40.6534 | L5: =SUM(B5:J5) -> 12879.012 | M5: =E5/L5 -> 0.56706679 | N5: =I5/L5 -> 0.40584868
A6: 1040 | B6: 11.5891 | C6: 57.4481 | D6: 164.342 | E6: 7447.27 | F6: 1.97398 | G6: 59.7171 | H6: 40.6786 | I6: 5237.02 | J6: 35.0764 | L6: =SUM(B6:J6) -> 13055.115 | M6: =E6/L6 -> 0.57044843 | N6: =I6/L6 -> 0.40114697
A7: 1192 | B7: 20.7916 | C7: 53.8394 | D7: 185.632 | E7: 7354.96 | F7: 6.15294 | G7: 58.4449 | H7: 42.8488 | I7: 5212.46 | J7: 41.6526 | L7: =SUM(B7:J7) -> 12976.782 | M7: =E7/L7 -> 0.56677841 | N7: =I7/L7 -> 0.40167585
A8: 1344 | B8: 18.1567 | C8: 56.3066 | D8: 199.535 | E8: 7294.09 | F8: 8.56183 | G8: 58.5363 | H8: 47.3579 | I8: 5168.57 | J8: 43.8896 | L8: =SUM(B8:J8) -> 12895.004 | M8: =E8/L8 -> 0.56565241 | N8: =I8/L8 -> 0.40081958
A9: 1496 | B9: 28.8142 | C9: 51.0927 | D9: 217.163 | E9: 7318.28 | F9: 8.41672 | G9: 68.1219 | H9: 42.1327 | I9: 5156.63 | J9: 40.7829 | L9: =SUM(B9:J9) -> 12931.434 | M9: =E9/L9 -> 0.5659295 | N9: =I9/L9 -> 0.39876706
A10: 1648 | B10: 30.7379 | C10: 51.5472 | D10: 232.659 | E10: 7369.87 | F10: 4.51628 | G10: 55.4376 | H10: 31.2262 | I10: 5146.93 | J10: 35.2736 | L10: =SUM(B10:J10) -> 12958.198 | M10: =E10/L10 -> 0.5687419 | N10: =I10/L10 -> 0.39719489
A11: 1800 | B11: 20.1718 | C11: 63.5608 | D11: 237.236 | E11: 7370.71 | F11: 11.5641 | G11: 56.3229 | H11: 44.2041 | I11: 5135.14 | J11: 35.1329 | L11: =SUM(B11:J11) -> 12974.043 | M11: =E11/L11 -> 0.56811205 | N11: =I11/L11 -> 0.39580107
A12: 1951 | B12: 32.6966 | C12: 66.743 | D12: 243.458 | E12: 7370.33 | F12: 11.9794 | G12: 52.5837 | H12: 45.1092 | I12: 5175.77 | J12: 45.6305 | L12: =SUM(B12:J12) -> 13044.3 | M12: =E12/L12 -> 0.56502302 | N12: =I12/L12 -> 0.39678402
A13: 2103 | B13: 28.3307 | C13: 65.5419 | D13: 253.872 | E13: 7372.86 | F13: 13.5803 | G13: 64.4898 | H13: 36.4389 | I13: 5158.99 | J13: 42.7497 | L13: =SUM(B13:J13) -> 13036.853 | M13: =E13/L13 -> 0.56553985 | N13: =I13/L13 -> 0.39572356
... A73: 11213 | B73: 37.3818 | C73: 66.0128 | D73: 305.969 | E73: 7430.06 | F73: 6.45541 | G73: 65.7123 | H73: 40.5466 | I73: 5065.2 | J73: 50.3644 | L73: =SUM(B73:J73) -> 13067.702 | M73: =E73/L73 -> 0.56858198 | N73: =I73/L73 -> 0.38761214
A75: ARR_DATA(I) | B75: Integral(6.300,6.244) | C75: Integral(6.190,6.153) | D75: Integral(6.151,6.078) | E75: Integral(6.000,5.965) | M75: f_dec_3
A76: 433 | B76: 0.578953 | C76: 31.9472 | D76: 7404.33 | E76: 20.061 | L76: =SUM(B76:J76) -> 7456.9172 | M76: =D76/L76 -> 0.99294787
A77: 585 | B77: 23.7144 | C77: 129.929 | D77: 7342.44 | E77: 17.6512 | L77: =SUM(B77:J77) -> 7513.7346 | M77: =D77/L77 -> 0.97720247
A78: 737 | B78: 35.2385 | C78: 146.801 | D78: 7341.19 | E78: 18.4467 | L78: =SUM(B78:J78) -> 7541.6762 | M78: =D78/L78 -> 0.97341623
A79: 889 | B79: 13.4191 | C79: 230.059 | D79: 7386.71 | E79: 19.4505 | L79: =SUM(B79:J79) -> 7649.6386 | M79: =D79/L79 -> 0.96562862
A80: 1040 | B80: 17.1066 | C80: 263.192 | D80: 7348.45 | E80: 12.3215 | L80: =SUM(B80:J80) -> 7641.0701 | M80: =D80/L80 -> 0.9617043
A81: 1192 | B81: 10.9385 | C81: 299.649 | D81: 7350.11 | E81: 27.3279 | L81: =SUM(B81:J81) -> 7688.0254 | M81: =D81/L81 -> 0.95604653
A82: 1344 | B82: 21.4009 | C82: 246.529 | D82: 7272.17 | E82: 27.4421 | L82: =SUM(B82:J82) -> 7567.542 | M82: =D82/L82 -> 0.96096857
A83: 1496 | B83: 34.2846 | C83: 308.135 | D83: 7311.92 | E83: 14.2666 | L83: =SUM(B83:J83) -> 7668.6062 | M83: =D83/L83 -> 0.95348748
A84: 1648 | B84: 9.84489 | C84: 288.406 | D84: 7272.86 | E84: 40.3939 | L84: =SUM(B84:J84) -> 7611.5048 | M84: =D84/L84 -> 0.95550883
A85: 1800 | B85: 37.4701 | C85: 283.531 | D85: 7233.25 | E85: 15.582 | L85: =SUM(B85:J85) -> 7569.8331 | M85: =D85/L85 -> 0.95553626
A86: 1951 | B86: 28.4372 | C86: 332.06 | D86: 7270.91 | E86: 14.2236 | L86: =SUM(B86:J86) -> 7645.6308 | M86: =D86/L86 -> 0.9509889
A87: 2103 | B87: 31.7587 | C87: 307.295 | D87: 7212.01 | E87: 15.6644 | L87: =SUM(B87:J87) -> 7566.7281 | M87: =D87/L87 -> 0.95312134
... A147: 11213 | B147: 65.5094 | C147: 315.198 | D147: 7137.1 | E147: 11.9435 | L147: =SUM(B147:J147) -> 7529.7509 | M147: =D147/L147 -> 0.9478534
A149: ARR_DATA(I) | B149: Integral(4.047,4.027)
A150: 433 | B150: 56823.4
A151: 585 | B151: 50516.4
A152: 737 | B152: 44539.9
A153: 889 | B153: 39325.6
A154: 1040 | B154: 34598.8
A155: 1192 | B155: 30799.5
A156: 1344 | B156: 27194.8
A157: 1496 | B157: 23918.5
A158: 1648 | B158: 21402.2
A159: 1800 | B159: 18684.9
A160: 1951 | B160: 16495.8
...

Sheet 42_1
A1: ARR_DATA(I) | B1: Integral(8.771,8.747) | C1: Integral(8.743,8.708) | D1: Integral(8.603,8.555) | E1: Integral(8.528,8.476) | F1: Integral(8.413,8.384) | G1: Integral(8.352,8.284) | H1: Integral(8.169,8.142) | L1: SUM | M1: f_dec_1 | N1: f_dec_2
A2: 490 | B2: 53.9032 | C2: 125.502 | D2: 7802.35 | E2: 56.0094 | F2: 27.0368 | G2: 5275.51 | H2: 50.9073 | L2: =SUM(B2:J2) -> 13391.219 | M2: =D2/L2 -> 0.58264675 | N2: =G2/L2 -> 0.39395294
A3: 612 | B3: 65.6351 | C3: 159.032 | D3: 7759.48 | E3: 45.6345 | F3: 47.7951 | G3: 5290.23 | H3: 53.2551 | L3: =SUM(B3:J3) -> 13421.062 | M3: =D3/L3 -> 0.57815694 | N3: =G3/L3 -> 0.39417373
A4: 734 | B4: 63.9923 | C4: 199.611 | D4: 7763.01 | E4: 57.9419 | F4: 40.0751 | G4: 5299.53 | H4: 34.9655 | L4: =SUM(B4:J4) -> 13459.126 | M4: =D4/L4 -> 0.57678412 | N4: =G4/L4 -> 0.39374994
A5: 856 | B5: 59.5574 | C5: 198.467 | D5: 7748.36 | E5: 54.7575 | F5: 30.8313 | G5: 5249.61 | H5: 42.8479 | L5: =SUM(B5:J5) -> 13384.431 | M5: =D5/L5 -> 0.57890843 | N5: =G5/L5 -> 0.39221764
A6: 977 | B6: 59.2329 | C6: 224.105 | D6: 7773.11 | E6: 61.2454 | F6: 46.3176 | G6: 5212.75 | H6: 39.5995 | L6: =SUM(B6:J6) -> 13416.36 | M6: =D6/L6 -> 0.57937546 | N6: =G6/L6 -> 0.38853682
A7: 1099 | B7: 48.2008 | C7: 220.888 | D7: 7776.56 | E7: 64.0808 | F7: 43.6603 | G7: 5238.65 | H7: 42.788 | L7: =SUM(B7:J7) -> 13434.828 | M7: =D7/L7 -> 0.57883585 | N7: =G7/L7 -> 0.38993056
A8: 1221 | B8: 52.8733 | C8: 253.288 | D8: 7757.7 | E8: 68.4733 | F8: 42.5096 | G8: 5244.55 | H8: 29.7132 | L8: =SUM(B8:J8) -> 13449.107 | M8: =D8/L8 -> 0.57681895 | N8: =G8/L8 -> 0.38995525
A9: 1343 | B9: 62.7555 | C9: 261.471 | D9: 7782.21 | E9: 61.2227 | F9: 33.7223 | G9: 5195.15 | H9: 32.0971 | L9: =SUM(B9:J9) -> 13428.629 | M9: =D9/L9 -> 0.57952381 | N9: =G9/L9 -> 0.38687123
A10: 1465 | B10: 73.0137 | C10: 282.949 | D10: 7756.91 | E10: 60.1436 | F10: 41.8257 | G10: 5204.19 | H10: 30.7495 | L10: =SUM(B10:J10) -> 13449.781 | M10: =D10/L10 -> 0.5767313 | N10: =G10/L10 -> 0.38693491
A11: 1587 | B11: 72.361 | C11: 273.217 | D11: 7761.44 | E11: 73.4642 | F11: 43.1435 | G11: 5144.31 | H11: 31.8194 | L11: =SUM(B11:J11) -> 13399.755 | M11: =D11/L11 -> 0.57922253 | N11: =G11/L11 -> 0.38391075
A12: 1709 | B12: 70.9749 | C12: 297.866 | D12: 7746.16 | E12: 59.1188 | F12: 43.1792 | G12: 5188.93 | H12: 49.9121 | L12: =SUM(B12:J12) -> 13456.141 | M12: =D12/L12 -> 0.57565984 | N12: =G12/L12 -> 0.38561799
A13: 1830 | B13: 68.8632 | C13: 288.225 | D13: 7722.96 | E13: 74.4688 | F13: 41.5222 | G13: 5184.08 | H13: 33.6167 | L13: =SUM(B13:J13) -> 13413.736 | M13: =D13/L13 -> 0.57575012 | N13: =G13/L13 -> 0.38647548
... A25: 3293 | B25: 78.0152 | C25: 319.76 | D25: 7716.02 | E25: 41.4745 | F25: 46.1713 | G25: 5158.24 | H25: 34.5956 | L25: =SUM(B25:J25) -> 13394.277 | M25: =D25/L25 -> 0.57606844 | N25: =G25/L25 -> 0.38510777
A27: ARR_DATA(I) | B27: Integral(6.353,6.302) | C27: Integral(6.244,6.206) | D27: Integral(6.204,6.137) | E27: Integral(6.062,6.018) | M27: f_dec_3
A28: 490 | B28: 13.3438 | C28: 161.239 | D28: 7774.23 | E28: 23.8317 | L28: =SUM(B28:J28) -> 7972.6445 | M28: =D28/L28 -> 0.97511309
A29: 612 | B29: 47.3928 | C29: 194.536 | D29: 7762.78 | E29: 27.2613 | L29: =SUM(B29:J29) -> 8031.9701 | M29: =D29/L29 -> 0.96648517
A30: 734 | B30: 21.2307 | C30: 266.947 | D30: 7786.89 | E30: 12.6613 | L30: =SUM(B30:J30) -> 8087.729 | M30: =D30/L30 -> 0.96280303
A31: 856 | B31: 14.8079 | C31: 242.265 | D31: 7767.88 | E31: 34.6855 | L31: =SUM(B31:J31) -> 8059.6384 | M31: =D31/L31 -> 0.96380006
A32: 977 | B32: 25.4859 | C32: 320.741 | D32: 7753.15 | E32: 26.6918 | L32: =SUM(B32:J32) -> 8126.0687 | M32: =D32/L32 -> 0.95410835
A33: 1099 | B33: 21.5947 | C33: 343.988 | D33: 7643.59 | E33: 47.4533 | L33: =SUM(B33:J33) -> 8056.626 | M33: =D33/L33 -> 0.94873338
A34: 1221 | B34: 32.5115 | C34: 295.264 | D34: 7719.28 | E34: 44.3271 | L34: =SUM(B34:J34) -> 8091.3826 | M34: =D34/L34 -> 0.95401248
A35: 1343 | B35: 41.4899 | C35: 287.661 | D35: 7699.26 | E35: 46.201 | L35: =SUM(B35:J35) -> 8074.6119 | M35: =D35/L35 -> 0.95351456
A36: 1465 | B36: 32.7645 | C36: 324.073 | D36: 7667.03 | E36: 16.6781 | L36: =SUM(B36:J36) -> 8040.5456 | M36: =D36/L36 -> 0.95354599
A37: 1587 | B37: 19.6143 | C37: 354.902 | D37: 7661.43 | E37: 29.5105 | L37: =SUM(B37:J37) -> 8065.4568 | M37: =D37/L37 -> 0.94990652
A38: 1709 | B38: 26.9005 | C38: 339.069 | D38: 7606.04 | E38: 17.2788 | L38: =SUM(B38:J38) -> 7989.2883 | M38: =D38/L38 -> 0.95202973
A39: 1830 | B39: 18.71 | C39: 336.156 | D39: 7639.6 | E39: 15.2146 | L39: =SUM(B39:J39) -> 8009.6806 | M39: =D39/L39 -> 0.95379584
... A51: 3293 | B51: 38.7827 | C51: 359.618 | D51: 7585.86 | E51: 20.7688 | L51: =SUM(B51:J51) -> 8005.0295 | M51: =D51/L51 -> 0.94763673
A53: ARR_DATA(I) | B53: Integral(4.104,4.084)
A54: 490 | B54: 40677 | L54: =SUM(B54:J54) -> 40677
A55: 612 | B55: 34331.8 | L55: =SUM(B55:J55) -> 34331.8
A56: 734 | B56: 29001.4 | L56: =SUM(B56:J56) -> 29001.4
A57: 856 | B57: 24591.1 | L57: =SUM(B57:J57) -> 24591.1
A58: 977 | B58: 20719.8 | L58: =SUM(B58:J58) -> 20719.8
A59: 1099 | B59: 17477.8 | L59: =SUM(B59:J59) -> 17477.8
A60: 1221 | B60: 14835.1 | L60: =SUM(B60:J60) -> 14835.1
A61: 1343 | B61: 12465.2 | L61: =SUM(B61:J61) -> 12465.2
A62: 1465 | B62: 10546.2 | L62: =SUM(B62:J62) -> 10546.2
A63: 1587 | B63: 8878.93 | L63: =SUM(B63:J63) -> 8878.93
A64: 1709 | B64: 7506.48 | L64: =SUM(B64:J64) -> 7506.48
...

Sheet 42_2
A1: ARR_DATA(I) | B1: Integral(8.769,8.743) | C1: Integral(8.740,8.701) | D1: Integral(8.614,8.542) | E1: Integral(8.526,8.473) | F1: Integral(8.416,8.384) | G1: Integral(8.347,8.280) | H1: Integral(8.168,8.136) | L1: SUM | M1: f_dec_1 | N1: f_dec_2
A2: 404 | B2: 48.4759 | C2: 126.697 | D2: 7511.92 | E2: 43.3033 | F2: 39.9355 | G2: 5258.63 | H2: 35.3577 | L2: =SUM(B2:J2) -> 13064.319 | M2: =D2/L2 -> 0.57499513 | N2: =G2/L2 -> 0.40251848
A3: 526 | B3: 64.0904 | C3: 154.166 | D3: 7577.61 | E3: 45.7552 | F3: 42.6395 | G3: 5189.85 | H3: 45.1621 | L3: =SUM(B3:J3) -> 13119.273 | M3: =D3/L3 -> 0.57759373 | N3: =G3/L3 -> 0.39558975
A4: 648 | B4: 69.7274 | C4: 157.323 | D4: 7471.9 | E4: 48.6132 | F4: 41.6913 | G4: 5154.8 | H4: 38.95 | L4: =SUM(B4:J4) -> 12983.005 | M4: =D4/L4 -> 0.57551392 | N4: =G4/L4 -> 0.39704214
A5: 770 | B5: 45.4988 | C5: 181.965 | D5: 7441.3 | E5: 39.431 | F5: 37.9233 | G5: 5174.24 | H5: 42.0296 | L5: =SUM(B5:J5) -> 12962.388 | M5: =D5/L5 -> 0.57406862 | N5: =G5/L5 -> 0.39917337
A6: 892 | B6: 67.2794 | C6: 211.496 | D6: 7502.7 | E6: 57.1962 | F6: 41.0956 | G6: 5139.79 | H6: 41.0961 | L6: =SUM(B6:J6) -> 13060.653 | M6: =D6/L6 -> 0.57445059 | N6: =G6/L6 -> 0.39353238
A7: 1014 | B7: 57.4429 | C7: 235.666 | D7: 7500.38 | E7: 47.7987 | F7: 33.8354 | G7: 5112.04 | H7: 48.3632 | L7: =SUM(B7:J7) -> 13035.526 | M7: =D7/L7 -> 0.57537992 | N7: =G7/L7 -> 0.39216215
A8: 1136 | B8: 65.6739 | C8: 223.143 | D8: 7481.51 | E8: 62.3024 | F8: 26.1977 | G8: 5081.6 | H8: 47.4556 | L8: =SUM(B8:J8) -> 12987.883 | M8: =D8/L8 -> 0.5760377 | N8: =G8/L8 -> 0.391257
A9: 1257 | B9: 75.5208 | C9: 247.039 | D9: 7582.28 | E9: 46.9488 | F9: 46.9124 | G9: 5190.98 | H9: 42.8932 | L9: =SUM(B9:J9) -> 13232.574 | M9: =D9/L9 -> 0.57300113 | N9: =G9/L9 -> 0.39228799
A10: 1379 | B10: 64.0786 | C10: 250.233 | D10: 7512.08 | E10: 54.7108 | F10: 38.7253 | G10: 5161.03 | H10: 47.1781 | L10: =SUM(B10:J10) -> 13128.036 | M10: =D10/L10 -> 0.5722166 | N10: =G10/L10 -> 0.3931304
A11: 1501 | B11: 57.1073 | C11: 266.924 | D11: 7547.93 | E11: 62.9622 | F11: 41.3343 | G11: 5119.1 | H11: 22.0375 | L11: =SUM(B11:J11) -> 13117.395 | M11: =D11/L11 -> 0.57541378 | N11: =G11/L11 -> 0.39025278
A12: 1623 | B12: 67.8909 | C12: 266.875 | D12: 7580.73 | E12: 66.914 | F12: 35.982 | G12: 5096.72 | H12: 41.8184 | L12: =SUM(B12:J12) -> 13156.93 | M12: =D12/L12 -> 0.57617771 | N12: =G12/L12 -> 0.38737911
A13: 1745 | B13: 51.4252 | C13: 281.963 | D13: 7540.52 | E13: 56.9277 | F13: 36.3198 | G13: 5083.91 | H13: 43.3745 | L13: =SUM(B13:J13) -> 13094.44 | M13: =D13/L13 -> 0.57585661 | N13: =G13/L13 -> 0.38824951
... A23: 2963 | B23: 69.877 | C23: 303.135 | D23: 7500.8 | E23: 72.8954 | F23: 50.0529 | G23: 5084.24 | H23: 49.9914 | L23: =SUM(B23:J23) -> 13130.992 | M23: =D23/L23 -> 0.57122875 | N23: =G23/L23 -> 0.38719391
A25: ARR_DATA(I) | B25: Integral(6.237,6.205) | C25: Integral(6.200,6.131) | D25: Integral(6.058,6.013) | E25: Integral(6.359,6.292) | M25: f_dec_3
A26: 404 | B26: 97.6026 | C26: 7686.02 | D26: 23.1652 | E26: 13.5015 | L26: =SUM(B26:J26) -> 7820.2893 | M26: =C26/L26 -> 0.98283065
A27: 526 | B27: 82.0423 | C27: 7457.17 | D27: 15.466 | E27: 2.22852 | L27: =SUM(B27:J27) -> 7556.9068 | M27: =C27/L27 -> 0.9868019
A28: 648 | B28: 215.618 | C28: 7477.1 | D28: 19.0919 | E28: 5.53845 | L28: =SUM(B28:J28) -> 7717.3484 | M28: =C28/L28 -> 0.96886905
A29: 770 | B29: 256.858 | C29: 7512.34 | D29: 21.5102 | E29: 15.4268 | L29: =SUM(B29:J29) -> 7806.135 | M29: =C29/L29 -> 0.96236358
A30: 892 | B30: 240.224 | C30: 7452.86 | D30: 23.9062 | E30: 19.7215 | L30: =SUM(B30:J30) -> 7736.7117 | M30: =C30/L30 -> 0.96331107
A31: 1014 | B31: 254.224 | C31: 7464.35 | D31: 20.0172 | E31: 5.25097 | L31: =SUM(B31:J31) -> 7743.8422 | M31: =C31/L31 -> 0.96390782
A32: 1136 | B32: 266.138 | C32: 7441.83 | D32: 4.86417 | E32: 13.8631 | L32: =SUM(B32:J32) -> 7726.6953 | M32: =C32/L32 -> 0.96313233
A33: 1257 | B33: 288.982 | C33: 7513.61 | D33: 14.8971 | E33: 25.1164 | L33: =SUM(B33:J33) -> 7842.6055 | M33: =C33/L33 -> 0.95805023
A34: 1379 | B34: 333.116 | C34: 7534.82 | D34: 15.0734 | E34: 19.7112 | L34: =SUM(B34:J34) -> 7902.7206 | M34: =C34/L34 -> 0.95344634
A35: 1501 | B35: 315.873 | C35: 7510.04 | D35: 26.7305 | E35: 39.125 | L35: =SUM(B35:J35) -> 7891.7685 | M35: =C35/L35 -> 0.95162954
A36: 1623 | B36: 323.165 | C36: 7483.98 | D36: 8.78581 | E36: 27.9438 | L36: =SUM(B36:J36) -> 7843.8746 | M36: =C36/L36 -> 0.95411775
A37: 1745 | B37: 328.561 | C37: 7464.33 | D37: 18.4192 | E37: 12.3291 | L37: =SUM(B37:J37) -> 7823.6393 | M37: =C37/L37 -> 0.95407389
... A47: 2963 | B47: 352.298 | C47: 7434.92 | D47: 31.6724 | E47: 25.3186 | L47: =SUM(B47:J47) -> 7844.209 | M47: =C47/L47 -> 0.94782278
A49: ARR_DATA(I) | B49: Integral(4.102,4.082)
A50: 404 | B50: 45853 | L50: =SUM(B50:J50) -> 45853
A51: 526 | B51: 38815 | L51: =SUM(B51:J51) -> 38815
A52: 648 | B52: 32399.3 | L52: =SUM(B52:J52) -> 32399.3
A53: 770 | B53: 27704.7 | L53: =SUM(B53:J53) -> 27704.7
A54: 892 | B54: 23516.4 | L54: =SUM(B54:J54) -> 23516.4
A55: 1014 | B55: 19993.8 | L55: =SUM(B55:J55) -> 19993.8
A56: 1136 | B56: 16985.9 | L56: =SUM(B56:J56) -> 16985.9
A57: 1257 | B57: 14413.9 | L57: =SUM(B57:J57) -> 14413.9
A58: 1379 | B58: 11977.1 | L58: =SUM(B58:J58) -> 11977.1
A59: 1501 | B59: 10337.8 | L59: =SUM(B59:J59) -> 10337.8
A60: 1623 | B60: 8759.3 | L60: =SUM(B60:J60) -> 8759.3
...

Sheet 48_1
A1: ARR_DATA(I) | B1: Integral(8.829,8.804) | C1: Integral(8.805,8.762) | D1: Integral(8.670,8.607) | E1: Integral(8.593,8.541) | F1: Integral(8.474,8.446) | G1: Integral(8.436,8.403) | H1: Integral(8.413,8.332) | I1: Integral(8.236,8.206) | L1: SUM | M1: f_dec_1 | N1: f_dec_2
A2: 288 | B2: 29.4404 | C2: 91.2855 | D2: 4671.03 | E2: 18.3847 | F2: 14.5921 | G2: 3.49981 | H2: 3118.05 | I2: 28.3179 | L2: =SUM(B2:J2) -> 7974.6004 | M2: =D2/L2 -> 0.58573844 | N2: =H2/L2 -> 0.39099765
A3: 380 | B3: 34.5498 | C3: 93.3948 | D3: 4638.38 | E3: 30.3795 | F3: 12.0482 | G3: 7.90283 | H3: 3144.6 | I3: 33.9318 | L3: =SUM(B3:J3) -> 7995.1869 | M3: =D3/L3 -> 0.58014654 | N3: =H3/L3 -> 0.39331163
A4: 472 | B4: 47.4495 | C4: 129.162 | D4: 4618.52 | E4: 31.5445 | F4: 26.7692 | G4: 19.5246 | H4: 3103.61 | I4: 24.545 | L4: =SUM(B4:J4) -> 8001.1248 | M4: =D4/L4 -> 0.57723384 | N4: =H4/L4 -> 0.38789671
A5: 564 | B5: 43.8397 | C5: 121.535 | D5: 4637.05 | E5: 33.8538 | F5: 18.4528 | G5: 13.365 | H5: 3088.37 | I5: 30.4691 | L5: =SUM(B5:J5) -> 7986.9354 | M5: =D5/L5 -> 0.58057938 | N5: =H5/L5 -> 0.38667772
A6: 656 | B6: 36.4662 | C6: 130.834 | D6: 4624.78 | E6: 42.328 | F6: 16.6687 | G6: 14.6173 | H6: 3041.85 | I6: 31.0895 | L6: =SUM(B6:J6) -> 7938.6337 | M6: =D6/L6 -> 0.58256624 | N6: =H6/L6 -> 0.38317047
A7: 747 | B7: 40.2404 | C7: 152.914 | D7: 4627.31 | E7: 47.3327 | F7: 13.1469 | G7: 64.327 | H7: 3067.58 | I7: 21.1382 | L7: =SUM(B7:J7) -> 8033.9892 | M7: =D7/L7 -> 0.57596667 | N7: =H7/L7 -> 0.38182526
A8: 839 | B8: 42.1977 | C8: 161.654 | D8: 4653.62 | E8: 42.2303 | F8: 16.2042 | G8: 19.1677 | H8: 3055.11 | I8: 8.69113 | L8: =SUM(B8:J8) -> 7998.875 | M8: =D8/L8 -> 0.58178431 | N8: =H8/L8 -> 0.38194246
A9: 931 | B9: 46.383 | C9: 166.9 | D9: 4610.85 | E9: 43.8592 | F9: 24.6826 | G9: 23.0993 | H9: 3053.93 | I9: 22.6143 | L9: =SUM(B9:J9) -> 7992.3184 | M9: =D9/L9 -> 0.5769102 | N9: =H9/L9 -> 0.38210815
A10: 1023 | B10: 33.0441 | C10: 160.803 | D10: 4610.69 | E10: 27.1026 | F10: 19.4788 | G10: 16.969 | H10: 3039.74 | I10: 26.5832 | L10: =SUM(B10:J10) -> 7934.4107 | M10: =D10/L10 -> 0.5811005 | N10: =H10/L10 -> 0.38310848
A11: 1115 | B11: 40.1389 | C11: 159.852 | D11: 4634.02 | E11: 43.0813 | F11: 22.0329 | G11: 30.7982 | H11: 3035.45 | I11: 28.6016 | L11: =SUM(B11:J11) -> 7993.9749 | M11: =D11/L11 -> 0.57968909 | N11: =H11/L11 -> 0.37971723
A12: 1207 | B12: 41.8937 | C12: 163.104 | D12: 4676.82 | E12: 43.4669 | F12: 30.1627 | G12: 25.2795 | H12: 3023.67 | I12: 20.6201 | L12: =SUM(B12:J12) -> 8025.0169 | M12: =D12/L12 -> 0.58278008 | N12: =H12/L12 -> 0.37678051
A13: 1299 | B13: 36.1323 | C13: 161.889 | D13: 4622.54 | E13: 40.9801 | F13: 30.3038 | G13: 24.9999 | H13: 3040.42 | I13: 29.2653 | L13: =SUM(B13:J13) -> 7986.5304 | M13: =D13/L13 -> 0.57879201 | N13: =H13/L13 -> 0.38069347
... A21: 2033 | B21: 36.485 | C21: 180.09 | D21: 4628.84 | E21: 43.2841 | F21: 25.15 | G21: 26.6012 | H21: 3008.1 | I21: 17.3783 | L21: =SUM(B21:J21) -> 7965.9286 | M21: =D21/L21 -> 0.58107978 | N21: =H21/L21 -> 0.37762076
A23: ARR_DATA(I) | B23: Integral(6.303,6.269) | C23: Integral(6.267,6.187) | M23: f_dec_3
A24: 288 | B24: 112.545 | C24: 4847.75 | L24: =SUM(B24:J24) -> 4960.295 | M24: =C24/L24 -> 0.97731083
A25: 380 | B25: 130.756 | C25: 4832.88 | L25: =SUM(B25:J25) -> 4963.636 | M25: =C25/L25 -> 0.97365721
A26: 472 | B26: 142.555 | C26: 4786.21 | L26: =SUM(B26:J26) -> 4928.765 | M26: =C26/L26 -> 0.97107693
A27: 564 | B27: 159.543 | C27: 4767.13 | L27: =SUM(B27:J27) -> 4926.673 | M27: =C27/L27 -> 0.96761648
A28: 656 | B28: 179.94 | C28: 4738.23 | L28: =SUM(B28:J28) -> 4918.17 | M28: =C28/L28 -> 0.96341322
A29: 747 | B29: 178.57 | C29: 4712.33 | L29: =SUM(B29:J29) -> 4890.9 | M29: =C29/L29 -> 0.96348934
A30: 839 | B30: 185.095 | C30: 4755.91 | L30: =SUM(B30:J30) -> 4941.005 | M30: =C30/L30 -> 0.962539
A31: 931 | B31: 183.056 | C31: 4731.88 | L31: =SUM(B31:J31) -> 4914.936 | M31: =C31/L31 -> 0.96275516
A32: 1023 | B32: 185.739 | C32: 4723.16 | L32: =SUM(B32:J32) -> 4908.899 | M32: =C32/L32 -> 0.9621628
A33: 1115 | B33: 195.979 | C33: 4727.26 | L33: =SUM(B33:J33) -> 4923.239 | M33: =C33/L33 -> 0.96019308
A34: 1207 | B34: 203.334 | C34: 4713.5 | L34: =SUM(B34:J34) -> 4916.834 | M34: =C34/L34 -> 0.95864534
A35: 1299 | B35: 190.022 | C35: 4727.56 | L35: =SUM(B35:J35) -> 4917.582 | M35: =C35/L35 -> 0.96135865
... A43: 2033 | B43: 197.396 | C43: 4701.33 | L43: =SUM(B43:J43) -> 4898.726 | M43: =C43/L43 -> 0.95970463
A45: ARR_DATA(I) | B45: Integral(4.170,4.143)
A46: 288 | B46: 27167.9 | L46: =SUM(B46:J46) -> 27167.9
A47: 380 | B47: 21552.9 | L47: =SUM(B47:J47) -> 21552.9
A48: 472 | B48: 17242.7 | L48: =SUM(B48:J48) -> 17242.7
A49: 564 | B49: 13448.3 | L49: =SUM(B49:J49) -> 13448.3
A50: 656 | B50: 10735.5 | L50: =SUM(B50:J50) -> 10735.5
A51: 747 | B51: 8477 | L51: =SUM(B51:J51) -> 8477
A52: 839 | B52: 6771.56 | L52: =SUM(B52:J52) -> 6771.56
A53: 931 | B53: 5391.41 | L53: =SUM(B53:J53) -> 5391.41
A54: 1023 | B54: 4240.01 | L54: =SUM(B54:J54) -> 4240.01
A55: 1115 | B55: 3298.12 | L55: =SUM(B55:J55) -> 3298.12
A56: 1207 | B56: 2661.86 | L56: =SUM(B56:J56) -> 2661.86
...

Sheet 48_2
A1: ARR_DATA(I) | B1: Integral(9.805,9.790) | C1: Integral(8.837,8.807) | D1: Integral(8.806,8.767) | E1: Integral(8.678,8.590) | F1: Integral(8.586,8.543) | G1: Integral(8.473,8.447) | H1: Integral(8.419,8.317) | I1: Integral(8.240,8.206) | L1: SUM | M1: f_dec_1 | N1: f_dec_2
A2: 365 | B2: 8.14509 | C2: 40.5094 | D2: 101.232 | E2: 4695.78 | F2: 40.0268 | G2: 30.2833 | H2: 3080.91 | I2: 25.6946 | L2: =SUM(B2:J2) -> 8022.5812 | M2: =D2/L2 -> 0.012618383 | N2: =H2/L2 -> 0.38402977
A3: 456 | B3: 7.33935 | C3: 43.7475 | D3: 112.826 | E3: 4675.58 | F3: 35.0461 | G3: 25.8019 | H3: 3033.3 | I3: 16.8739 | L3: =SUM(B3:J3) -> 7950.5147 | M3: =D3/L3 -> 0.014191031 | N3: =H3/L3 -> 0.38152247
A4: 548 | B4: 12.9047 | C4: 42.6501 | D4: 122.804 | E4: 4633.76 | F4: 42.6195 | G4: 26.9204 | H4: 3031.99 | I4: 21.129 | L4: =SUM(B4:J4) -> 7934.7777 | M4: =D4/L4 -> 0.015476678 | N4: =H4/L4 -> 0.38211404
A5: 640 | B5: 14.7706 | C5: 39.9794 | D5: 134.58 | E5: 4626.87 | F5: 42.0261 | G5: 27.3702 | H5: 3024.5 | I5: 25.6699 | L5: =SUM(B5:J5) -> 7935.7662 | M5: =D5/L5 -> 0.016958665 | N5: =H5/L5 -> 0.38112262
A6: 732 | B6: 20.9985 | C6: 41.6611 | D6: 147.669 | E6: 4681.43 | F6: 43.4451 | G6: 27.5282 | H6: 3043.91 | I6: 26.16 | L6: =SUM(B6:J6) -> 8032.8019 | M6: =D6/L6 -> 0.018383249 | N6: =H6/L6 -> 0.37893503
A7: 824 | B7: 14.1169 | C7: 27.1023 | D7: 149.165 | E7: 4599.23 | F7: 44.6033 | G7: 20.1541 | H7: 3003.48 | I7: 25.8008 | L7: =SUM(B7:J7) -> 7883.6524 | M7: =D7/L7 -> 0.018920799 | N7: =H7/L7 -> 0.3809757
A8: 916 | B8: 18.2781 | C8: 42.9649 | D8: 160.25 | E8: 4630.73 | F8: 45.7932 | G8: 25.2748 | H8: 3070.21 | I8: 10.3029 | L8: =SUM(B8:J8) -> 8003.8039 | M8: =D8/L8 -> 0.02002173 | N8: =H8/L8 -> 0.38359386
A9: 1008 | B9: 7.69454 | C9: 33.0462 | D9: 170.168 | E9: 4664.75 | F9: 41.3871 | G9: 24.9263 | H9: 3046.64 | I9: 15.8391 | L9: =SUM(B9:J9) -> 8004.4512 | M9: =D9/L9 -> 0.021259171 | N9: =H9/L9 -> 0.38061822
A10: 1099 | B10: 16.5581 | C10: 48.0848 | D10: 179.158 | E10: 4632.56 | F10: 54.36 | G10: 26.0187 | H10: 3008.3 | I10: 33.7553 | L10: =SUM(B10:J10) -> 7998.7949 | M10: =D10/L10 -> 0.022398124 | N10: =H10/L10 -> 0.37609415
A11: 1191 | B11: 10.0216 | C11: 49.8999 | D11: 185.632 | E11: 4633.9 | F11: 53.1596 | G11: 33.1435 | H11: 2978.5 | I11: 23.4902 | L11: =SUM(B11:J11) -> 7967.7468 | M11: =D11/L11 -> 0.023297929 | N11: =H11/L11 -> 0.37381961
A12: 1283 | B12: 9.3729 | C12: 48.5325 | D12: 175.147 | E12: 4615.03 | F12: 50.4471 | G12: 20.3417 | H12: 3064.14 | I12: 24.2023 | L12: =SUM(B12:J12) -> 8007.2135 | M12: =D12/L12 -> 0.021873652 | N12: =H12/L12 -> 0.38267245
A13: 1375 | B13: 17.7785 | C13: 41.5297 | D13: 181.756 | E13: 4632.69 | F13: 62.0742 | G13: 22.6535 | H13: 3002 | I13: 22.8068 | L13: =SUM(B13:J13) -> 7983.2887 | M13: =D13/L13 -> 0.022767058 | N13: =H13/L13 -> 0.37603551
... A21: 2110 | B21: 21.5545 | C21: 41.017 | D21: 172.501 | E21: 4671.52 | F21: 49.5976 | G21: 32.4169 | H21: 2928.07 | I21: 34.3882 | L21: =SUM(B21:J21) -> 7951.0652 | M21: =D21/L21 -> 0.021695332 | N21: =H21/L21 -> 0.36826135
A23: ARR_DATA(I) | B23: Integral(6.303,6.268) | C23: Integral(6.266,6.197) | D23: Integral(6.396,6.368) | E23: Integral(6.116,6.086) | M23: f_dec_3
A24: 365 | B24: 72.9868 | C24: 4792.23 | D24: 10.7532 | E24: 9.66141 | L24: =SUM(B24:J24) -> 4885.6314 | M24: =C24/L24 -> 0.98088243
A25: 456 | B25: 95.6634 | C25: 4802.11 | D25: 0.336004 | E25: 16.7019 | L25: =SUM(B25:J25) -> 4914.8113 | M25: =C25/L25 -> 0.97706905
A26: 548 | B26: 125.485 | C26: 4752.06 | D26: 9.77689 | E26: 17.4741 | L26: =SUM(B26:J26) -> 4904.796 | M26: =C26/L26 -> 0.96885987
A27: 640 | B27: 146.837 | C27: 4724.37 | D27: 10.0709 | E27: 16.5291 | L27: =SUM(B27:J27) -> 4897.807 | M27: =C27/L27 -> 0.96458885
A28: 732 | B28: 135.321 | C28: 4708.49 | D28: 7.87035 | E28: 18.0899 | L28: =SUM(B28:J28) -> 4869.7712 | M28: =C28/L28 -> 0.96688114
A29: 824 | B29: 131.353 | C29: 4670.57 | D29: 4.44741 | E29: 5.04616 | L29: =SUM(B29:J29) -> 4811.4166 | M29: =C29/L29 -> 0.97072659
A30: 916 | B30: 168.843 | C30: 4712.29 | D30: 10.1055 | E30: 18.6461 | L30: =SUM(B30:J30) -> 4909.8846 | M30: =C30/L30 -> 0.95975575
A31: 1008 | B31: 126.35 | C31: 4675.67 | D31: 11.8235 | E31: 14.3419 | L31: =SUM(B31:J31) -> 4828.1854 | M31: =C31/L31 -> 0.96841145
A32: 1099 | B32: 158.768 | C32: 4673.76 | D32: 8.59216 | E32: 16.8954 | L32: =SUM(B32:J32) -> 4858.0156 | M32: =C32/L32 -> 0.96207185
A33: 1191 | B33: 136.331 | C33: 4658.26 | D33: 4.3307 | E33: 12.2175 | L33: =SUM(B33:J33) -> 4811.1392 | M33: =C33/L33 -> 0.96822391
A34: 1283 | B34: 176.454 | C34: 4709.43 | D34: 0.8443 | E34: 13.1077 | L34: =SUM(B34:J34) -> 4899.836 | M34: =C34/L34 -> 0.96114033
A35: 1375 | B35: 162.523 | C35: 4706.98 | D35: 5.19288 | E35: 11.4128 | L35: =SUM(B35:J35) -> 4886.1087 | M35: =C35/L35 -> 0.96333919
... A43: 2110 | B43: 284.334 | C43: 4699.03 | D43: 5.78343 | E43: 14.5538 | L43: =SUM(B43:J43) -> 5003.7012 | M43: =C43/L43 -> 0.93911083
A45: ARR_DATA(I) | B45: Integral(4.171,4.145)
A46: 365 | B46: 22665.4 | L46: =SUM(B46:J46) -> 22665.4
A47: 456 | B47: 17932.5 | L47: =SUM(B47:J47) -> 17932.5
A48: 548 | B48: 13930.7 | L48: =SUM(B48:J48) -> 13930.7
A49: 640 | B49: 11126.1 | L49: =SUM(B49:J49) -> 11126.1
A50: 732 | B50: 8914.91 | L50: =SUM(B50:J50) -> 8914.91
A51: 824 | B51: 7001.71 | L51: =SUM(B51:J51) -> 7001.71
A52: 916 | B52: 5539.69 | L52: =SUM(B52:J52) -> 5539.69
A53: 1008 | B53: 4346.57 | L53: =SUM(B53:J53) -> 4346.57
A54: 1099 | B54: 3532.08 | L54: =SUM(B54:J54) -> 3532.08
A55: 1191 | B55: 2669.37 | L55: =SUM(B55:J55) -> 2669.37
A56: 1283 | B56: 2152.77 | L56: =SUM(B56:J56) -> 2152.77
...
